nohup: ignoring input
/home/yousefmsm1/Desktop/1.7/venv/lib/python3.12/site-packages/telegram/utils/request.py:49: UserWarning: python-telegram-bot is using upstream urllib3. This is allowed but not supported by python-telegram-bot maintainers.
  warnings.warn(
/home/yousefmsm1/Desktop/1.7/venv/lib/python3.12/site-packages/apscheduler/__init__.py:1: UserWarning: pkg_resources is deprecated as an API. See https://setuptools.pypa.io/en/latest/pkg_resources.html. The pkg_resources package is slated for removal as early as 2025-11-30. Refrain from using this package or pin to Setuptools<81.
  from pkg_resources import get_distribution, DistributionNotFound
2025-06-23 19:39:03,404 - apscheduler.scheduler - INFO - Scheduler started
2025-06-23 19:39:07,869 - price_sticker_bot - INFO - Bot started. Press Ctrl+C to stop.
2025-06-23 19:39:15,392 - telegram.ext.updater - ERROR - Error while getting Updates: Conflict: terminated by other getUpdates request; make sure that only one bot instance is running
2025-06-23 19:39:15,392 - telegram.ext.dispatcher - ERROR - No error handlers are registered, logging exception.
Traceback (most recent call last):
  File "/home/yousefmsm1/Desktop/1.7/venv/lib/python3.12/site-packages/telegram/ext/updater.py", line 651, in _network_loop_retry
    if not action_cb():
           ^^^^^^^^^^^
  File "/home/yousefmsm1/Desktop/1.7/venv/lib/python3.12/site-packages/telegram/ext/updater.py", line 602, in polling_action_cb
    updates = self.bot.get_updates(
              ^^^^^^^^^^^^^^^^^^^^^
  File "/home/yousefmsm1/Desktop/1.7/venv/lib/python3.12/site-packages/telegram/ext/extbot.py", line 228, in get_updates
    updates = super().get_updates(
              ^^^^^^^^^^^^^^^^^^^^
  File "/home/yousefmsm1/Desktop/1.7/venv/lib/python3.12/site-packages/telegram/bot.py", line 134, in decorator
    result = func(*args, **kwargs)
             ^^^^^^^^^^^^^^^^^^^^^
  File "/home/yousefmsm1/Desktop/1.7/venv/lib/python3.12/site-packages/telegram/bot.py", line 3140, in get_updates
    self._post(
  File "/home/yousefmsm1/Desktop/1.7/venv/lib/python3.12/site-packages/telegram/bot.py", line 299, in _post
    return self.request.post(
           ^^^^^^^^^^^^^^^^^^
  File "/home/yousefmsm1/Desktop/1.7/venv/lib/python3.12/site-packages/telegram/utils/request.py", line 361, in post
    result = self._request_wrapper(
             ^^^^^^^^^^^^^^^^^^^^^^
  File "/home/yousefmsm1/Desktop/1.7/venv/lib/python3.12/site-packages/telegram/utils/request.py", line 283, in _request_wrapper
    raise Conflict(message)
telegram.error.Conflict: Conflict: terminated by other getUpdates request; make sure that only one bot instance is running
2025-06-23 19:39:23,283 - telegram.ext.updater - ERROR - Error while getting Updates: Conflict: terminated by other getUpdates request; make sure that only one bot instance is running
2025-06-23 19:39:23,289 - telegram.ext.dispatcher - ERROR - No error handlers are registered, logging exception.
Traceback (most recent call last):
  File "/home/yousefmsm1/Desktop/1.7/venv/lib/python3.12/site-packages/telegram/ext/updater.py", line 651, in _network_loop_retry
    if not action_cb():
           ^^^^^^^^^^^
  File "/home/yousefmsm1/Desktop/1.7/venv/lib/python3.12/site-packages/telegram/ext/updater.py", line 602, in polling_action_cb
    updates = self.bot.get_updates(
              ^^^^^^^^^^^^^^^^^^^^^
  File "/home/yousefmsm1/Desktop/1.7/venv/lib/python3.12/site-packages/telegram/ext/extbot.py", line 228, in get_updates
    updates = super().get_updates(
              ^^^^^^^^^^^^^^^^^^^^
  File "/home/yousefmsm1/Desktop/1.7/venv/lib/python3.12/site-packages/telegram/bot.py", line 134, in decorator
    result = func(*args, **kwargs)
             ^^^^^^^^^^^^^^^^^^^^^
  File "/home/yousefmsm1/Desktop/1.7/venv/lib/python3.12/site-packages/telegram/bot.py", line 3140, in get_updates
    self._post(
  File "/home/yousefmsm1/Desktop/1.7/venv/lib/python3.12/site-packages/telegram/bot.py", line 299, in _post
    return self.request.post(
           ^^^^^^^^^^^^^^^^^^
  File "/home/yousefmsm1/Desktop/1.7/venv/lib/python3.12/site-packages/telegram/utils/request.py", line 361, in post
    result = self._request_wrapper(
             ^^^^^^^^^^^^^^^^^^^^^^
  File "/home/yousefmsm1/Desktop/1.7/venv/lib/python3.12/site-packages/telegram/utils/request.py", line 283, in _request_wrapper
    raise Conflict(message)
telegram.error.Conflict: Conflict: terminated by other getUpdates request; make sure that only one bot instance is running
2025-06-23 19:39:29,592 - telegram.ext.updater - ERROR - Error while getting Updates: Unauthorized
2025-06-23 19:39:29,592 - telegram.ext.dispatcher - ERROR - No error handlers are registered, logging exception.
Traceback (most recent call last):
  File "/home/yousefmsm1/Desktop/1.7/venv/lib/python3.12/site-packages/telegram/ext/updater.py", line 651, in _network_loop_retry
    if not action_cb():
           ^^^^^^^^^^^
  File "/home/yousefmsm1/Desktop/1.7/venv/lib/python3.12/site-packages/telegram/ext/updater.py", line 602, in polling_action_cb
    updates = self.bot.get_updates(
              ^^^^^^^^^^^^^^^^^^^^^
  File "/home/yousefmsm1/Desktop/1.7/venv/lib/python3.12/site-packages/telegram/ext/extbot.py", line 228, in get_updates
    updates = super().get_updates(
              ^^^^^^^^^^^^^^^^^^^^
  File "/home/yousefmsm1/Desktop/1.7/venv/lib/python3.12/site-packages/telegram/bot.py", line 134, in decorator
    result = func(*args, **kwargs)
             ^^^^^^^^^^^^^^^^^^^^^
  File "/home/yousefmsm1/Desktop/1.7/venv/lib/python3.12/site-packages/telegram/bot.py", line 3140, in get_updates
    self._post(
  File "/home/yousefmsm1/Desktop/1.7/venv/lib/python3.12/site-packages/telegram/bot.py", line 299, in _post
    return self.request.post(
           ^^^^^^^^^^^^^^^^^^
  File "/home/yousefmsm1/Desktop/1.7/venv/lib/python3.12/site-packages/telegram/utils/request.py", line 361, in post
    result = self._request_wrapper(
             ^^^^^^^^^^^^^^^^^^^^^^
  File "/home/yousefmsm1/Desktop/1.7/venv/lib/python3.12/site-packages/telegram/utils/request.py", line 277, in _request_wrapper
    raise Unauthorized(message)
telegram.error.Unauthorized: Unauthorized
2025-06-23 19:39:31,088 - telegram.ext.updater - ERROR - Error while getting Updates: Unauthorized
2025-06-23 19:39:31,089 - telegram.ext.dispatcher - ERROR - No error handlers are registered, logging exception.
Traceback (most recent call last):
  File "/home/yousefmsm1/Desktop/1.7/venv/lib/python3.12/site-packages/telegram/ext/updater.py", line 651, in _network_loop_retry
    if not action_cb():
           ^^^^^^^^^^^
  File "/home/yousefmsm1/Desktop/1.7/venv/lib/python3.12/site-packages/telegram/ext/updater.py", line 602, in polling_action_cb
    updates = self.bot.get_updates(
              ^^^^^^^^^^^^^^^^^^^^^
  File "/home/yousefmsm1/Desktop/1.7/venv/lib/python3.12/site-packages/telegram/ext/extbot.py", line 228, in get_updates
    updates = super().get_updates(
              ^^^^^^^^^^^^^^^^^^^^
  File "/home/yousefmsm1/Desktop/1.7/venv/lib/python3.12/site-packages/telegram/bot.py", line 134, in decorator
    result = func(*args, **kwargs)
             ^^^^^^^^^^^^^^^^^^^^^
  File "/home/yousefmsm1/Desktop/1.7/venv/lib/python3.12/site-packages/telegram/bot.py", line 3140, in get_updates
    self._post(
  File "/home/yousefmsm1/Desktop/1.7/venv/lib/python3.12/site-packages/telegram/bot.py", line 299, in _post
    return self.request.post(
           ^^^^^^^^^^^^^^^^^^
  File "/home/yousefmsm1/Desktop/1.7/venv/lib/python3.12/site-packages/telegram/utils/request.py", line 361, in post
    result = self._request_wrapper(
             ^^^^^^^^^^^^^^^^^^^^^^
  File "/home/yousefmsm1/Desktop/1.7/venv/lib/python3.12/site-packages/telegram/utils/request.py", line 277, in _request_wrapper
    raise Unauthorized(message)
telegram.error.Unauthorized: Unauthorized
2025-06-23 19:39:32,691 - telegram.ext.updater - ERROR - Error while getting Updates: Unauthorized
2025-06-23 19:39:32,692 - telegram.ext.dispatcher - ERROR - No error handlers are registered, logging exception.
Traceback (most recent call last):
  File "/home/yousefmsm1/Desktop/1.7/venv/lib/python3.12/site-packages/telegram/ext/updater.py", line 651, in _network_loop_retry
    if not action_cb():
           ^^^^^^^^^^^
  File "/home/yousefmsm1/Desktop/1.7/venv/lib/python3.12/site-packages/telegram/ext/updater.py", line 602, in polling_action_cb
    updates = self.bot.get_updates(
              ^^^^^^^^^^^^^^^^^^^^^
  File "/home/yousefmsm1/Desktop/1.7/venv/lib/python3.12/site-packages/telegram/ext/extbot.py", line 228, in get_updates
    updates = super().get_updates(
              ^^^^^^^^^^^^^^^^^^^^
  File "/home/yousefmsm1/Desktop/1.7/venv/lib/python3.12/site-packages/telegram/bot.py", line 134, in decorator
    result = func(*args, **kwargs)
             ^^^^^^^^^^^^^^^^^^^^^
  File "/home/yousefmsm1/Desktop/1.7/venv/lib/python3.12/site-packages/telegram/bot.py", line 3140, in get_updates
    self._post(
  File "/home/yousefmsm1/Desktop/1.7/venv/lib/python3.12/site-packages/telegram/bot.py", line 299, in _post
    return self.request.post(
           ^^^^^^^^^^^^^^^^^^
  File "/home/yousefmsm1/Desktop/1.7/venv/lib/python3.12/site-packages/telegram/utils/request.py", line 361, in post
    result = self._request_wrapper(
             ^^^^^^^^^^^^^^^^^^^^^^
  File "/home/yousefmsm1/Desktop/1.7/venv/lib/python3.12/site-packages/telegram/utils/request.py", line 277, in _request_wrapper
    raise Unauthorized(message)
telegram.error.Unauthorized: Unauthorized
2025-06-23 19:39:35,096 - telegram.ext.updater - ERROR - Error while getting Updates: Unauthorized
2025-06-23 19:39:35,096 - telegram.ext.dispatcher - ERROR - No error handlers are registered, logging exception.
Traceback (most recent call last):
  File "/home/yousefmsm1/Desktop/1.7/venv/lib/python3.12/site-packages/telegram/ext/updater.py", line 651, in _network_loop_retry
    if not action_cb():
           ^^^^^^^^^^^
  File "/home/yousefmsm1/Desktop/1.7/venv/lib/python3.12/site-packages/telegram/ext/updater.py", line 602, in polling_action_cb
    updates = self.bot.get_updates(
              ^^^^^^^^^^^^^^^^^^^^^
  File "/home/yousefmsm1/Desktop/1.7/venv/lib/python3.12/site-packages/telegram/ext/extbot.py", line 228, in get_updates
    updates = super().get_updates(
              ^^^^^^^^^^^^^^^^^^^^
  File "/home/yousefmsm1/Desktop/1.7/venv/lib/python3.12/site-packages/telegram/bot.py", line 134, in decorator
    result = func(*args, **kwargs)
             ^^^^^^^^^^^^^^^^^^^^^
  File "/home/yousefmsm1/Desktop/1.7/venv/lib/python3.12/site-packages/telegram/bot.py", line 3140, in get_updates
    self._post(
  File "/home/yousefmsm1/Desktop/1.7/venv/lib/python3.12/site-packages/telegram/bot.py", line 299, in _post
    return self.request.post(
           ^^^^^^^^^^^^^^^^^^
  File "/home/yousefmsm1/Desktop/1.7/venv/lib/python3.12/site-packages/telegram/utils/request.py", line 361, in post
    result = self._request_wrapper(
             ^^^^^^^^^^^^^^^^^^^^^^
  File "/home/yousefmsm1/Desktop/1.7/venv/lib/python3.12/site-packages/telegram/utils/request.py", line 277, in _request_wrapper
    raise Unauthorized(message)
telegram.error.Unauthorized: Unauthorized
2025-06-23 19:39:38,920 - telegram.ext.updater - ERROR - Error while getting Updates: Unauthorized
2025-06-23 19:39:38,920 - telegram.ext.dispatcher - ERROR - No error handlers are registered, logging exception.
Traceback (most recent call last):
  File "/home/yousefmsm1/Desktop/1.7/venv/lib/python3.12/site-packages/telegram/ext/updater.py", line 651, in _network_loop_retry
    if not action_cb():
           ^^^^^^^^^^^
  File "/home/yousefmsm1/Desktop/1.7/venv/lib/python3.12/site-packages/telegram/ext/updater.py", line 602, in polling_action_cb
    updates = self.bot.get_updates(
              ^^^^^^^^^^^^^^^^^^^^^
  File "/home/yousefmsm1/Desktop/1.7/venv/lib/python3.12/site-packages/telegram/ext/extbot.py", line 228, in get_updates
    updates = super().get_updates(
              ^^^^^^^^^^^^^^^^^^^^
  File "/home/yousefmsm1/Desktop/1.7/venv/lib/python3.12/site-packages/telegram/bot.py", line 134, in decorator
    result = func(*args, **kwargs)
             ^^^^^^^^^^^^^^^^^^^^^
  File "/home/yousefmsm1/Desktop/1.7/venv/lib/python3.12/site-packages/telegram/bot.py", line 3140, in get_updates
    self._post(
  File "/home/yousefmsm1/Desktop/1.7/venv/lib/python3.12/site-packages/telegram/bot.py", line 299, in _post
    return self.request.post(
           ^^^^^^^^^^^^^^^^^^
  File "/home/yousefmsm1/Desktop/1.7/venv/lib/python3.12/site-packages/telegram/utils/request.py", line 361, in post
    result = self._request_wrapper(
             ^^^^^^^^^^^^^^^^^^^^^^
  File "/home/yousefmsm1/Desktop/1.7/venv/lib/python3.12/site-packages/telegram/utils/request.py", line 277, in _request_wrapper
    raise Unauthorized(message)
telegram.error.Unauthorized: Unauthorized
2025-06-23 19:39:47,912 - telegram.ext.updater - ERROR - Error while getting Updates: Unauthorized
2025-06-23 19:39:47,913 - telegram.ext.dispatcher - ERROR - No error handlers are registered, logging exception.
Traceback (most recent call last):
  File "/home/yousefmsm1/Desktop/1.7/venv/lib/python3.12/site-packages/telegram/ext/updater.py", line 651, in _network_loop_retry
    if not action_cb():
           ^^^^^^^^^^^
  File "/home/yousefmsm1/Desktop/1.7/venv/lib/python3.12/site-packages/telegram/ext/updater.py", line 602, in polling_action_cb
    updates = self.bot.get_updates(
              ^^^^^^^^^^^^^^^^^^^^^
  File "/home/yousefmsm1/Desktop/1.7/venv/lib/python3.12/site-packages/telegram/ext/extbot.py", line 228, in get_updates
    updates = super().get_updates(
              ^^^^^^^^^^^^^^^^^^^^
  File "/home/yousefmsm1/Desktop/1.7/venv/lib/python3.12/site-packages/telegram/bot.py", line 134, in decorator
    result = func(*args, **kwargs)
             ^^^^^^^^^^^^^^^^^^^^^
  File "/home/yousefmsm1/Desktop/1.7/venv/lib/python3.12/site-packages/telegram/bot.py", line 3140, in get_updates
    self._post(
  File "/home/yousefmsm1/Desktop/1.7/venv/lib/python3.12/site-packages/telegram/bot.py", line 299, in _post
    return self.request.post(
           ^^^^^^^^^^^^^^^^^^
  File "/home/yousefmsm1/Desktop/1.7/venv/lib/python3.12/site-packages/telegram/utils/request.py", line 361, in post
    result = self._request_wrapper(
             ^^^^^^^^^^^^^^^^^^^^^^
  File "/home/yousefmsm1/Desktop/1.7/venv/lib/python3.12/site-packages/telegram/utils/request.py", line 277, in _request_wrapper
    raise Unauthorized(message)
telegram.error.Unauthorized: Unauthorized
2025-06-23 19:39:55,767 - telegram.ext.updater - ERROR - Error while getting Updates: Unauthorized
2025-06-23 19:39:55,768 - telegram.ext.dispatcher - ERROR - No error handlers are registered, logging exception.
Traceback (most recent call last):
  File "/home/yousefmsm1/Desktop/1.7/venv/lib/python3.12/site-packages/telegram/ext/updater.py", line 651, in _network_loop_retry
    if not action_cb():
           ^^^^^^^^^^^
  File "/home/yousefmsm1/Desktop/1.7/venv/lib/python3.12/site-packages/telegram/ext/updater.py", line 602, in polling_action_cb
    updates = self.bot.get_updates(
              ^^^^^^^^^^^^^^^^^^^^^
  File "/home/yousefmsm1/Desktop/1.7/venv/lib/python3.12/site-packages/telegram/ext/extbot.py", line 228, in get_updates
    updates = super().get_updates(
              ^^^^^^^^^^^^^^^^^^^^
  File "/home/yousefmsm1/Desktop/1.7/venv/lib/python3.12/site-packages/telegram/bot.py", line 134, in decorator
    result = func(*args, **kwargs)
             ^^^^^^^^^^^^^^^^^^^^^
  File "/home/yousefmsm1/Desktop/1.7/venv/lib/python3.12/site-packages/telegram/bot.py", line 3140, in get_updates
    self._post(
  File "/home/yousefmsm1/Desktop/1.7/venv/lib/python3.12/site-packages/telegram/bot.py", line 299, in _post
    return self.request.post(
           ^^^^^^^^^^^^^^^^^^
  File "/home/yousefmsm1/Desktop/1.7/venv/lib/python3.12/site-packages/telegram/utils/request.py", line 361, in post
    result = self._request_wrapper(
             ^^^^^^^^^^^^^^^^^^^^^^
  File "/home/yousefmsm1/Desktop/1.7/venv/lib/python3.12/site-packages/telegram/utils/request.py", line 277, in _request_wrapper
    raise Unauthorized(message)
telegram.error.Unauthorized: Unauthorized
2025-06-23 19:40:07,430 - telegram.ext.updater - ERROR - Error while getting Updates: Unauthorized
2025-06-23 19:40:07,430 - telegram.ext.dispatcher - ERROR - No error handlers are registered, logging exception.
Traceback (most recent call last):
  File "/home/yousefmsm1/Desktop/1.7/venv/lib/python3.12/site-packages/telegram/ext/updater.py", line 651, in _network_loop_retry
    if not action_cb():
           ^^^^^^^^^^^
  File "/home/yousefmsm1/Desktop/1.7/venv/lib/python3.12/site-packages/telegram/ext/updater.py", line 602, in polling_action_cb
    updates = self.bot.get_updates(
              ^^^^^^^^^^^^^^^^^^^^^
  File "/home/yousefmsm1/Desktop/1.7/venv/lib/python3.12/site-packages/telegram/ext/extbot.py", line 228, in get_updates
    updates = super().get_updates(
              ^^^^^^^^^^^^^^^^^^^^
  File "/home/yousefmsm1/Desktop/1.7/venv/lib/python3.12/site-packages/telegram/bot.py", line 134, in decorator
    result = func(*args, **kwargs)
             ^^^^^^^^^^^^^^^^^^^^^
  File "/home/yousefmsm1/Desktop/1.7/venv/lib/python3.12/site-packages/telegram/bot.py", line 3140, in get_updates
    self._post(
  File "/home/yousefmsm1/Desktop/1.7/venv/lib/python3.12/site-packages/telegram/bot.py", line 299, in _post
    return self.request.post(
           ^^^^^^^^^^^^^^^^^^
  File "/home/yousefmsm1/Desktop/1.7/venv/lib/python3.12/site-packages/telegram/utils/request.py", line 361, in post
    result = self._request_wrapper(
             ^^^^^^^^^^^^^^^^^^^^^^
  File "/home/yousefmsm1/Desktop/1.7/venv/lib/python3.12/site-packages/telegram/utils/request.py", line 277, in _request_wrapper
    raise Unauthorized(message)
telegram.error.Unauthorized: Unauthorized
2025-06-23 19:40:24,670 - telegram.ext.updater - ERROR - Error while getting Updates: Unauthorized
2025-06-23 19:40:24,671 - telegram.ext.dispatcher - ERROR - No error handlers are registered, logging exception.
Traceback (most recent call last):
  File "/home/yousefmsm1/Desktop/1.7/venv/lib/python3.12/site-packages/telegram/ext/updater.py", line 651, in _network_loop_retry
    if not action_cb():
           ^^^^^^^^^^^
  File "/home/yousefmsm1/Desktop/1.7/venv/lib/python3.12/site-packages/telegram/ext/updater.py", line 602, in polling_action_cb
    updates = self.bot.get_updates(
              ^^^^^^^^^^^^^^^^^^^^^
  File "/home/yousefmsm1/Desktop/1.7/venv/lib/python3.12/site-packages/telegram/ext/extbot.py", line 228, in get_updates
    updates = super().get_updates(
              ^^^^^^^^^^^^^^^^^^^^
  File "/home/yousefmsm1/Desktop/1.7/venv/lib/python3.12/site-packages/telegram/bot.py", line 134, in decorator
    result = func(*args, **kwargs)
             ^^^^^^^^^^^^^^^^^^^^^
  File "/home/yousefmsm1/Desktop/1.7/venv/lib/python3.12/site-packages/telegram/bot.py", line 3140, in get_updates
    self._post(
  File "/home/yousefmsm1/Desktop/1.7/venv/lib/python3.12/site-packages/telegram/bot.py", line 299, in _post
    return self.request.post(
           ^^^^^^^^^^^^^^^^^^
  File "/home/yousefmsm1/Desktop/1.7/venv/lib/python3.12/site-packages/telegram/utils/request.py", line 361, in post
    result = self._request_wrapper(
             ^^^^^^^^^^^^^^^^^^^^^^
  File "/home/yousefmsm1/Desktop/1.7/venv/lib/python3.12/site-packages/telegram/utils/request.py", line 277, in _request_wrapper
    raise Unauthorized(message)
telegram.error.Unauthorized: Unauthorized
2025-06-23 19:40:50,569 - telegram.ext.updater - ERROR - Error while getting Updates: Unauthorized
2025-06-23 19:40:50,569 - telegram.ext.dispatcher - ERROR - No error handlers are registered, logging exception.
Traceback (most recent call last):
  File "/home/yousefmsm1/Desktop/1.7/venv/lib/python3.12/site-packages/telegram/ext/updater.py", line 651, in _network_loop_retry
    if not action_cb():
           ^^^^^^^^^^^
  File "/home/yousefmsm1/Desktop/1.7/venv/lib/python3.12/site-packages/telegram/ext/updater.py", line 602, in polling_action_cb
    updates = self.bot.get_updates(
              ^^^^^^^^^^^^^^^^^^^^^
  File "/home/yousefmsm1/Desktop/1.7/venv/lib/python3.12/site-packages/telegram/ext/extbot.py", line 228, in get_updates
    updates = super().get_updates(
              ^^^^^^^^^^^^^^^^^^^^
  File "/home/yousefmsm1/Desktop/1.7/venv/lib/python3.12/site-packages/telegram/bot.py", line 134, in decorator
    result = func(*args, **kwargs)
             ^^^^^^^^^^^^^^^^^^^^^
  File "/home/yousefmsm1/Desktop/1.7/venv/lib/python3.12/site-packages/telegram/bot.py", line 3140, in get_updates
    self._post(
  File "/home/yousefmsm1/Desktop/1.7/venv/lib/python3.12/site-packages/telegram/bot.py", line 299, in _post
    return self.request.post(
           ^^^^^^^^^^^^^^^^^^
  File "/home/yousefmsm1/Desktop/1.7/venv/lib/python3.12/site-packages/telegram/utils/request.py", line 361, in post
    result = self._request_wrapper(
             ^^^^^^^^^^^^^^^^^^^^^^
  File "/home/yousefmsm1/Desktop/1.7/venv/lib/python3.12/site-packages/telegram/utils/request.py", line 277, in _request_wrapper
    raise Unauthorized(message)
telegram.error.Unauthorized: Unauthorized
2025-06-23 19:41:29,527 - telegram.ext.updater - ERROR - Error while getting Updates: Unauthorized
2025-06-23 19:41:29,527 - telegram.ext.dispatcher - ERROR - No error handlers are registered, logging exception.
Traceback (most recent call last):
  File "/home/yousefmsm1/Desktop/1.7/venv/lib/python3.12/site-packages/telegram/ext/updater.py", line 651, in _network_loop_retry
    if not action_cb():
           ^^^^^^^^^^^
  File "/home/yousefmsm1/Desktop/1.7/venv/lib/python3.12/site-packages/telegram/ext/updater.py", line 602, in polling_action_cb
    updates = self.bot.get_updates(
              ^^^^^^^^^^^^^^^^^^^^^
  File "/home/yousefmsm1/Desktop/1.7/venv/lib/python3.12/site-packages/telegram/ext/extbot.py", line 228, in get_updates
    updates = super().get_updates(
              ^^^^^^^^^^^^^^^^^^^^
  File "/home/yousefmsm1/Desktop/1.7/venv/lib/python3.12/site-packages/telegram/bot.py", line 134, in decorator
    result = func(*args, **kwargs)
             ^^^^^^^^^^^^^^^^^^^^^
  File "/home/yousefmsm1/Desktop/1.7/venv/lib/python3.12/site-packages/telegram/bot.py", line 3140, in get_updates
    self._post(
  File "/home/yousefmsm1/Desktop/1.7/venv/lib/python3.12/site-packages/telegram/bot.py", line 299, in _post
    return self.request.post(
           ^^^^^^^^^^^^^^^^^^
  File "/home/yousefmsm1/Desktop/1.7/venv/lib/python3.12/site-packages/telegram/utils/request.py", line 361, in post
    result = self._request_wrapper(
             ^^^^^^^^^^^^^^^^^^^^^^
  File "/home/yousefmsm1/Desktop/1.7/venv/lib/python3.12/site-packages/telegram/utils/request.py", line 277, in _request_wrapper
    raise Unauthorized(message)
telegram.error.Unauthorized: Unauthorized
2025-06-23 19:41:59,742 - telegram.ext.updater - ERROR - Error while getting Updates: Unauthorized
2025-06-23 19:41:59,743 - telegram.ext.dispatcher - ERROR - No error handlers are registered, logging exception.
Traceback (most recent call last):
  File "/home/yousefmsm1/Desktop/1.7/venv/lib/python3.12/site-packages/telegram/ext/updater.py", line 651, in _network_loop_retry
    if not action_cb():
           ^^^^^^^^^^^
  File "/home/yousefmsm1/Desktop/1.7/venv/lib/python3.12/site-packages/telegram/ext/updater.py", line 602, in polling_action_cb
    updates = self.bot.get_updates(
              ^^^^^^^^^^^^^^^^^^^^^
  File "/home/yousefmsm1/Desktop/1.7/venv/lib/python3.12/site-packages/telegram/ext/extbot.py", line 228, in get_updates
    updates = super().get_updates(
              ^^^^^^^^^^^^^^^^^^^^
  File "/home/yousefmsm1/Desktop/1.7/venv/lib/python3.12/site-packages/telegram/bot.py", line 134, in decorator
    result = func(*args, **kwargs)
             ^^^^^^^^^^^^^^^^^^^^^
  File "/home/yousefmsm1/Desktop/1.7/venv/lib/python3.12/site-packages/telegram/bot.py", line 3140, in get_updates
    self._post(
  File "/home/yousefmsm1/Desktop/1.7/venv/lib/python3.12/site-packages/telegram/bot.py", line 299, in _post
    return self.request.post(
           ^^^^^^^^^^^^^^^^^^
  File "/home/yousefmsm1/Desktop/1.7/venv/lib/python3.12/site-packages/telegram/utils/request.py", line 361, in post
    result = self._request_wrapper(
             ^^^^^^^^^^^^^^^^^^^^^^
  File "/home/yousefmsm1/Desktop/1.7/venv/lib/python3.12/site-packages/telegram/utils/request.py", line 277, in _request_wrapper
    raise Unauthorized(message)
telegram.error.Unauthorized: Unauthorized
2025-06-23 19:42:29,897 - telegram.ext.updater - ERROR - Error while getting Updates: Unauthorized
2025-06-23 19:42:29,898 - telegram.ext.dispatcher - ERROR - No error handlers are registered, logging exception.
Traceback (most recent call last):
  File "/home/yousefmsm1/Desktop/1.7/venv/lib/python3.12/site-packages/telegram/ext/updater.py", line 651, in _network_loop_retry
    if not action_cb():
           ^^^^^^^^^^^
  File "/home/yousefmsm1/Desktop/1.7/venv/lib/python3.12/site-packages/telegram/ext/updater.py", line 602, in polling_action_cb
    updates = self.bot.get_updates(
              ^^^^^^^^^^^^^^^^^^^^^
  File "/home/yousefmsm1/Desktop/1.7/venv/lib/python3.12/site-packages/telegram/ext/extbot.py", line 228, in get_updates
    updates = super().get_updates(
              ^^^^^^^^^^^^^^^^^^^^
  File "/home/yousefmsm1/Desktop/1.7/venv/lib/python3.12/site-packages/telegram/bot.py", line 134, in decorator
    result = func(*args, **kwargs)
             ^^^^^^^^^^^^^^^^^^^^^
  File "/home/yousefmsm1/Desktop/1.7/venv/lib/python3.12/site-packages/telegram/bot.py", line 3140, in get_updates
    self._post(
  File "/home/yousefmsm1/Desktop/1.7/venv/lib/python3.12/site-packages/telegram/bot.py", line 299, in _post
    return self.request.post(
           ^^^^^^^^^^^^^^^^^^
  File "/home/yousefmsm1/Desktop/1.7/venv/lib/python3.12/site-packages/telegram/utils/request.py", line 361, in post
    result = self._request_wrapper(
             ^^^^^^^^^^^^^^^^^^^^^^
  File "/home/yousefmsm1/Desktop/1.7/venv/lib/python3.12/site-packages/telegram/utils/request.py", line 277, in _request_wrapper
    raise Unauthorized(message)
telegram.error.Unauthorized: Unauthorized
2025-06-23 19:42:59,970 - telegram.ext.updater - ERROR - Error while getting Updates: Unauthorized
2025-06-23 19:42:59,970 - telegram.ext.dispatcher - ERROR - No error handlers are registered, logging exception.
Traceback (most recent call last):
  File "/home/yousefmsm1/Desktop/1.7/venv/lib/python3.12/site-packages/telegram/ext/updater.py", line 651, in _network_loop_retry
    if not action_cb():
           ^^^^^^^^^^^
  File "/home/yousefmsm1/Desktop/1.7/venv/lib/python3.12/site-packages/telegram/ext/updater.py", line 602, in polling_action_cb
    updates = self.bot.get_updates(
              ^^^^^^^^^^^^^^^^^^^^^
  File "/home/yousefmsm1/Desktop/1.7/venv/lib/python3.12/site-packages/telegram/ext/extbot.py", line 228, in get_updates
    updates = super().get_updates(
              ^^^^^^^^^^^^^^^^^^^^
  File "/home/yousefmsm1/Desktop/1.7/venv/lib/python3.12/site-packages/telegram/bot.py", line 134, in decorator
    result = func(*args, **kwargs)
             ^^^^^^^^^^^^^^^^^^^^^
  File "/home/yousefmsm1/Desktop/1.7/venv/lib/python3.12/site-packages/telegram/bot.py", line 3140, in get_updates
    self._post(
  File "/home/yousefmsm1/Desktop/1.7/venv/lib/python3.12/site-packages/telegram/bot.py", line 299, in _post
    return self.request.post(
           ^^^^^^^^^^^^^^^^^^
  File "/home/yousefmsm1/Desktop/1.7/venv/lib/python3.12/site-packages/telegram/utils/request.py", line 361, in post
    result = self._request_wrapper(
             ^^^^^^^^^^^^^^^^^^^^^^
  File "/home/yousefmsm1/Desktop/1.7/venv/lib/python3.12/site-packages/telegram/utils/request.py", line 277, in _request_wrapper
    raise Unauthorized(message)
telegram.error.Unauthorized: Unauthorized
2025-06-23 19:43:30,041 - telegram.ext.updater - ERROR - Error while getting Updates: Unauthorized
2025-06-23 19:43:30,041 - telegram.ext.dispatcher - ERROR - No error handlers are registered, logging exception.
Traceback (most recent call last):
  File "/home/yousefmsm1/Desktop/1.7/venv/lib/python3.12/site-packages/telegram/ext/updater.py", line 651, in _network_loop_retry
    if not action_cb():
           ^^^^^^^^^^^
  File "/home/yousefmsm1/Desktop/1.7/venv/lib/python3.12/site-packages/telegram/ext/updater.py", line 602, in polling_action_cb
    updates = self.bot.get_updates(
              ^^^^^^^^^^^^^^^^^^^^^
  File "/home/yousefmsm1/Desktop/1.7/venv/lib/python3.12/site-packages/telegram/ext/extbot.py", line 228, in get_updates
    updates = super().get_updates(
              ^^^^^^^^^^^^^^^^^^^^
  File "/home/yousefmsm1/Desktop/1.7/venv/lib/python3.12/site-packages/telegram/bot.py", line 134, in decorator
    result = func(*args, **kwargs)
             ^^^^^^^^^^^^^^^^^^^^^
  File "/home/yousefmsm1/Desktop/1.7/venv/lib/python3.12/site-packages/telegram/bot.py", line 3140, in get_updates
    self._post(
  File "/home/yousefmsm1/Desktop/1.7/venv/lib/python3.12/site-packages/telegram/bot.py", line 299, in _post
    return self.request.post(
           ^^^^^^^^^^^^^^^^^^
  File "/home/yousefmsm1/Desktop/1.7/venv/lib/python3.12/site-packages/telegram/utils/request.py", line 361, in post
    result = self._request_wrapper(
             ^^^^^^^^^^^^^^^^^^^^^^
  File "/home/yousefmsm1/Desktop/1.7/venv/lib/python3.12/site-packages/telegram/utils/request.py", line 277, in _request_wrapper
    raise Unauthorized(message)
telegram.error.Unauthorized: Unauthorized
2025-06-23 19:44:00,218 - telegram.ext.updater - ERROR - Error while getting Updates: Unauthorized
2025-06-23 19:44:00,218 - telegram.ext.dispatcher - ERROR - No error handlers are registered, logging exception.
Traceback (most recent call last):
  File "/home/yousefmsm1/Desktop/1.7/venv/lib/python3.12/site-packages/telegram/ext/updater.py", line 651, in _network_loop_retry
    if not action_cb():
           ^^^^^^^^^^^
  File "/home/yousefmsm1/Desktop/1.7/venv/lib/python3.12/site-packages/telegram/ext/updater.py", line 602, in polling_action_cb
    updates = self.bot.get_updates(
              ^^^^^^^^^^^^^^^^^^^^^
  File "/home/yousefmsm1/Desktop/1.7/venv/lib/python3.12/site-packages/telegram/ext/extbot.py", line 228, in get_updates
    updates = super().get_updates(
              ^^^^^^^^^^^^^^^^^^^^
  File "/home/yousefmsm1/Desktop/1.7/venv/lib/python3.12/site-packages/telegram/bot.py", line 134, in decorator
    result = func(*args, **kwargs)
             ^^^^^^^^^^^^^^^^^^^^^
  File "/home/yousefmsm1/Desktop/1.7/venv/lib/python3.12/site-packages/telegram/bot.py", line 3140, in get_updates
    self._post(
  File "/home/yousefmsm1/Desktop/1.7/venv/lib/python3.12/site-packages/telegram/bot.py", line 299, in _post
    return self.request.post(
           ^^^^^^^^^^^^^^^^^^
  File "/home/yousefmsm1/Desktop/1.7/venv/lib/python3.12/site-packages/telegram/utils/request.py", line 361, in post
    result = self._request_wrapper(
             ^^^^^^^^^^^^^^^^^^^^^^
  File "/home/yousefmsm1/Desktop/1.7/venv/lib/python3.12/site-packages/telegram/utils/request.py", line 277, in _request_wrapper
    raise Unauthorized(message)
telegram.error.Unauthorized: Unauthorized
2025-06-23 19:44:30,292 - telegram.ext.updater - ERROR - Error while getting Updates: Unauthorized
2025-06-23 19:44:30,292 - telegram.ext.dispatcher - ERROR - No error handlers are registered, logging exception.
Traceback (most recent call last):
  File "/home/yousefmsm1/Desktop/1.7/venv/lib/python3.12/site-packages/telegram/ext/updater.py", line 651, in _network_loop_retry
    if not action_cb():
           ^^^^^^^^^^^
  File "/home/yousefmsm1/Desktop/1.7/venv/lib/python3.12/site-packages/telegram/ext/updater.py", line 602, in polling_action_cb
    updates = self.bot.get_updates(
              ^^^^^^^^^^^^^^^^^^^^^
  File "/home/yousefmsm1/Desktop/1.7/venv/lib/python3.12/site-packages/telegram/ext/extbot.py", line 228, in get_updates
    updates = super().get_updates(
              ^^^^^^^^^^^^^^^^^^^^
  File "/home/yousefmsm1/Desktop/1.7/venv/lib/python3.12/site-packages/telegram/bot.py", line 134, in decorator
    result = func(*args, **kwargs)
             ^^^^^^^^^^^^^^^^^^^^^
  File "/home/yousefmsm1/Desktop/1.7/venv/lib/python3.12/site-packages/telegram/bot.py", line 3140, in get_updates
    self._post(
  File "/home/yousefmsm1/Desktop/1.7/venv/lib/python3.12/site-packages/telegram/bot.py", line 299, in _post
    return self.request.post(
           ^^^^^^^^^^^^^^^^^^
  File "/home/yousefmsm1/Desktop/1.7/venv/lib/python3.12/site-packages/telegram/utils/request.py", line 361, in post
    result = self._request_wrapper(
             ^^^^^^^^^^^^^^^^^^^^^^
  File "/home/yousefmsm1/Desktop/1.7/venv/lib/python3.12/site-packages/telegram/utils/request.py", line 277, in _request_wrapper
    raise Unauthorized(message)
telegram.error.Unauthorized: Unauthorized
2025-06-23 19:45:00,362 - telegram.ext.updater - ERROR - Error while getting Updates: Unauthorized
2025-06-23 19:45:00,362 - telegram.ext.dispatcher - ERROR - No error handlers are registered, logging exception.
Traceback (most recent call last):
  File "/home/yousefmsm1/Desktop/1.7/venv/lib/python3.12/site-packages/telegram/ext/updater.py", line 651, in _network_loop_retry
    if not action_cb():
           ^^^^^^^^^^^
  File "/home/yousefmsm1/Desktop/1.7/venv/lib/python3.12/site-packages/telegram/ext/updater.py", line 602, in polling_action_cb
    updates = self.bot.get_updates(
              ^^^^^^^^^^^^^^^^^^^^^
  File "/home/yousefmsm1/Desktop/1.7/venv/lib/python3.12/site-packages/telegram/ext/extbot.py", line 228, in get_updates
    updates = super().get_updates(
              ^^^^^^^^^^^^^^^^^^^^
  File "/home/yousefmsm1/Desktop/1.7/venv/lib/python3.12/site-packages/telegram/bot.py", line 134, in decorator
    result = func(*args, **kwargs)
             ^^^^^^^^^^^^^^^^^^^^^
  File "/home/yousefmsm1/Desktop/1.7/venv/lib/python3.12/site-packages/telegram/bot.py", line 3140, in get_updates
    self._post(
  File "/home/yousefmsm1/Desktop/1.7/venv/lib/python3.12/site-packages/telegram/bot.py", line 299, in _post
    return self.request.post(
           ^^^^^^^^^^^^^^^^^^
  File "/home/yousefmsm1/Desktop/1.7/venv/lib/python3.12/site-packages/telegram/utils/request.py", line 361, in post
    result = self._request_wrapper(
             ^^^^^^^^^^^^^^^^^^^^^^
  File "/home/yousefmsm1/Desktop/1.7/venv/lib/python3.12/site-packages/telegram/utils/request.py", line 277, in _request_wrapper
    raise Unauthorized(message)
telegram.error.Unauthorized: Unauthorized
2025-06-23 19:45:30,432 - telegram.ext.updater - ERROR - Error while getting Updates: Unauthorized
2025-06-23 19:45:30,433 - telegram.ext.dispatcher - ERROR - No error handlers are registered, logging exception.
Traceback (most recent call last):
  File "/home/yousefmsm1/Desktop/1.7/venv/lib/python3.12/site-packages/telegram/ext/updater.py", line 651, in _network_loop_retry
    if not action_cb():
           ^^^^^^^^^^^
  File "/home/yousefmsm1/Desktop/1.7/venv/lib/python3.12/site-packages/telegram/ext/updater.py", line 602, in polling_action_cb
    updates = self.bot.get_updates(
              ^^^^^^^^^^^^^^^^^^^^^
  File "/home/yousefmsm1/Desktop/1.7/venv/lib/python3.12/site-packages/telegram/ext/extbot.py", line 228, in get_updates
    updates = super().get_updates(
              ^^^^^^^^^^^^^^^^^^^^
  File "/home/yousefmsm1/Desktop/1.7/venv/lib/python3.12/site-packages/telegram/bot.py", line 134, in decorator
    result = func(*args, **kwargs)
             ^^^^^^^^^^^^^^^^^^^^^
  File "/home/yousefmsm1/Desktop/1.7/venv/lib/python3.12/site-packages/telegram/bot.py", line 3140, in get_updates
    self._post(
  File "/home/yousefmsm1/Desktop/1.7/venv/lib/python3.12/site-packages/telegram/bot.py", line 299, in _post
    return self.request.post(
           ^^^^^^^^^^^^^^^^^^
  File "/home/yousefmsm1/Desktop/1.7/venv/lib/python3.12/site-packages/telegram/utils/request.py", line 361, in post
    result = self._request_wrapper(
             ^^^^^^^^^^^^^^^^^^^^^^
  File "/home/yousefmsm1/Desktop/1.7/venv/lib/python3.12/site-packages/telegram/utils/request.py", line 277, in _request_wrapper
    raise Unauthorized(message)
telegram.error.Unauthorized: Unauthorized
2025-06-23 19:46:00,509 - telegram.ext.updater - ERROR - Error while getting Updates: Unauthorized
2025-06-23 19:46:00,509 - telegram.ext.dispatcher - ERROR - No error handlers are registered, logging exception.
Traceback (most recent call last):
  File "/home/yousefmsm1/Desktop/1.7/venv/lib/python3.12/site-packages/telegram/ext/updater.py", line 651, in _network_loop_retry
    if not action_cb():
           ^^^^^^^^^^^
  File "/home/yousefmsm1/Desktop/1.7/venv/lib/python3.12/site-packages/telegram/ext/updater.py", line 602, in polling_action_cb
    updates = self.bot.get_updates(
              ^^^^^^^^^^^^^^^^^^^^^
  File "/home/yousefmsm1/Desktop/1.7/venv/lib/python3.12/site-packages/telegram/ext/extbot.py", line 228, in get_updates
    updates = super().get_updates(
              ^^^^^^^^^^^^^^^^^^^^
  File "/home/yousefmsm1/Desktop/1.7/venv/lib/python3.12/site-packages/telegram/bot.py", line 134, in decorator
    result = func(*args, **kwargs)
             ^^^^^^^^^^^^^^^^^^^^^
  File "/home/yousefmsm1/Desktop/1.7/venv/lib/python3.12/site-packages/telegram/bot.py", line 3140, in get_updates
    self._post(
  File "/home/yousefmsm1/Desktop/1.7/venv/lib/python3.12/site-packages/telegram/bot.py", line 299, in _post
    return self.request.post(
           ^^^^^^^^^^^^^^^^^^
  File "/home/yousefmsm1/Desktop/1.7/venv/lib/python3.12/site-packages/telegram/utils/request.py", line 361, in post
    result = self._request_wrapper(
             ^^^^^^^^^^^^^^^^^^^^^^
  File "/home/yousefmsm1/Desktop/1.7/venv/lib/python3.12/site-packages/telegram/utils/request.py", line 277, in _request_wrapper
    raise Unauthorized(message)
telegram.error.Unauthorized: Unauthorized
2025-06-23 19:46:30,581 - telegram.ext.updater - ERROR - Error while getting Updates: Unauthorized
2025-06-23 19:46:30,582 - telegram.ext.dispatcher - ERROR - No error handlers are registered, logging exception.
Traceback (most recent call last):
  File "/home/yousefmsm1/Desktop/1.7/venv/lib/python3.12/site-packages/telegram/ext/updater.py", line 651, in _network_loop_retry
    if not action_cb():
           ^^^^^^^^^^^
  File "/home/yousefmsm1/Desktop/1.7/venv/lib/python3.12/site-packages/telegram/ext/updater.py", line 602, in polling_action_cb
    updates = self.bot.get_updates(
              ^^^^^^^^^^^^^^^^^^^^^
  File "/home/yousefmsm1/Desktop/1.7/venv/lib/python3.12/site-packages/telegram/ext/extbot.py", line 228, in get_updates
    updates = super().get_updates(
              ^^^^^^^^^^^^^^^^^^^^
  File "/home/yousefmsm1/Desktop/1.7/venv/lib/python3.12/site-packages/telegram/bot.py", line 134, in decorator
    result = func(*args, **kwargs)
             ^^^^^^^^^^^^^^^^^^^^^
  File "/home/yousefmsm1/Desktop/1.7/venv/lib/python3.12/site-packages/telegram/bot.py", line 3140, in get_updates
    self._post(
  File "/home/yousefmsm1/Desktop/1.7/venv/lib/python3.12/site-packages/telegram/bot.py", line 299, in _post
    return self.request.post(
           ^^^^^^^^^^^^^^^^^^
  File "/home/yousefmsm1/Desktop/1.7/venv/lib/python3.12/site-packages/telegram/utils/request.py", line 361, in post
    result = self._request_wrapper(
             ^^^^^^^^^^^^^^^^^^^^^^
  File "/home/yousefmsm1/Desktop/1.7/venv/lib/python3.12/site-packages/telegram/utils/request.py", line 277, in _request_wrapper
    raise Unauthorized(message)
telegram.error.Unauthorized: Unauthorized
2025-06-23 19:47:00,652 - telegram.ext.updater - ERROR - Error while getting Updates: Unauthorized
2025-06-23 19:47:00,652 - telegram.ext.dispatcher - ERROR - No error handlers are registered, logging exception.
Traceback (most recent call last):
  File "/home/yousefmsm1/Desktop/1.7/venv/lib/python3.12/site-packages/telegram/ext/updater.py", line 651, in _network_loop_retry
    if not action_cb():
           ^^^^^^^^^^^
  File "/home/yousefmsm1/Desktop/1.7/venv/lib/python3.12/site-packages/telegram/ext/updater.py", line 602, in polling_action_cb
    updates = self.bot.get_updates(
              ^^^^^^^^^^^^^^^^^^^^^
  File "/home/yousefmsm1/Desktop/1.7/venv/lib/python3.12/site-packages/telegram/ext/extbot.py", line 228, in get_updates
    updates = super().get_updates(
              ^^^^^^^^^^^^^^^^^^^^
  File "/home/yousefmsm1/Desktop/1.7/venv/lib/python3.12/site-packages/telegram/bot.py", line 134, in decorator
    result = func(*args, **kwargs)
             ^^^^^^^^^^^^^^^^^^^^^
  File "/home/yousefmsm1/Desktop/1.7/venv/lib/python3.12/site-packages/telegram/bot.py", line 3140, in get_updates
    self._post(
  File "/home/yousefmsm1/Desktop/1.7/venv/lib/python3.12/site-packages/telegram/bot.py", line 299, in _post
    return self.request.post(
           ^^^^^^^^^^^^^^^^^^
  File "/home/yousefmsm1/Desktop/1.7/venv/lib/python3.12/site-packages/telegram/utils/request.py", line 361, in post
    result = self._request_wrapper(
             ^^^^^^^^^^^^^^^^^^^^^^
  File "/home/yousefmsm1/Desktop/1.7/venv/lib/python3.12/site-packages/telegram/utils/request.py", line 277, in _request_wrapper
    raise Unauthorized(message)
telegram.error.Unauthorized: Unauthorized
2025-06-23 19:47:30,724 - telegram.ext.updater - ERROR - Error while getting Updates: Unauthorized
2025-06-23 19:47:30,724 - telegram.ext.dispatcher - ERROR - No error handlers are registered, logging exception.
Traceback (most recent call last):
  File "/home/yousefmsm1/Desktop/1.7/venv/lib/python3.12/site-packages/telegram/ext/updater.py", line 651, in _network_loop_retry
    if not action_cb():
           ^^^^^^^^^^^
  File "/home/yousefmsm1/Desktop/1.7/venv/lib/python3.12/site-packages/telegram/ext/updater.py", line 602, in polling_action_cb
    updates = self.bot.get_updates(
              ^^^^^^^^^^^^^^^^^^^^^
  File "/home/yousefmsm1/Desktop/1.7/venv/lib/python3.12/site-packages/telegram/ext/extbot.py", line 228, in get_updates
    updates = super().get_updates(
              ^^^^^^^^^^^^^^^^^^^^
  File "/home/yousefmsm1/Desktop/1.7/venv/lib/python3.12/site-packages/telegram/bot.py", line 134, in decorator
    result = func(*args, **kwargs)
             ^^^^^^^^^^^^^^^^^^^^^
  File "/home/yousefmsm1/Desktop/1.7/venv/lib/python3.12/site-packages/telegram/bot.py", line 3140, in get_updates
    self._post(
  File "/home/yousefmsm1/Desktop/1.7/venv/lib/python3.12/site-packages/telegram/bot.py", line 299, in _post
    return self.request.post(
           ^^^^^^^^^^^^^^^^^^
  File "/home/yousefmsm1/Desktop/1.7/venv/lib/python3.12/site-packages/telegram/utils/request.py", line 361, in post
    result = self._request_wrapper(
             ^^^^^^^^^^^^^^^^^^^^^^
  File "/home/yousefmsm1/Desktop/1.7/venv/lib/python3.12/site-packages/telegram/utils/request.py", line 277, in _request_wrapper
    raise Unauthorized(message)
telegram.error.Unauthorized: Unauthorized
2025-06-23 19:48:00,797 - telegram.ext.updater - ERROR - Error while getting Updates: Unauthorized
2025-06-23 19:48:00,798 - telegram.ext.dispatcher - ERROR - No error handlers are registered, logging exception.
Traceback (most recent call last):
  File "/home/yousefmsm1/Desktop/1.7/venv/lib/python3.12/site-packages/telegram/ext/updater.py", line 651, in _network_loop_retry
    if not action_cb():
           ^^^^^^^^^^^
  File "/home/yousefmsm1/Desktop/1.7/venv/lib/python3.12/site-packages/telegram/ext/updater.py", line 602, in polling_action_cb
    updates = self.bot.get_updates(
              ^^^^^^^^^^^^^^^^^^^^^
  File "/home/yousefmsm1/Desktop/1.7/venv/lib/python3.12/site-packages/telegram/ext/extbot.py", line 228, in get_updates
    updates = super().get_updates(
              ^^^^^^^^^^^^^^^^^^^^
  File "/home/yousefmsm1/Desktop/1.7/venv/lib/python3.12/site-packages/telegram/bot.py", line 134, in decorator
    result = func(*args, **kwargs)
             ^^^^^^^^^^^^^^^^^^^^^
  File "/home/yousefmsm1/Desktop/1.7/venv/lib/python3.12/site-packages/telegram/bot.py", line 3140, in get_updates
    self._post(
  File "/home/yousefmsm1/Desktop/1.7/venv/lib/python3.12/site-packages/telegram/bot.py", line 299, in _post
    return self.request.post(
           ^^^^^^^^^^^^^^^^^^
  File "/home/yousefmsm1/Desktop/1.7/venv/lib/python3.12/site-packages/telegram/utils/request.py", line 361, in post
    result = self._request_wrapper(
             ^^^^^^^^^^^^^^^^^^^^^^
  File "/home/yousefmsm1/Desktop/1.7/venv/lib/python3.12/site-packages/telegram/utils/request.py", line 277, in _request_wrapper
    raise Unauthorized(message)
telegram.error.Unauthorized: Unauthorized
2025-06-23 19:48:30,895 - telegram.ext.updater - ERROR - Error while getting Updates: Unauthorized
2025-06-23 19:48:30,895 - telegram.ext.dispatcher - ERROR - No error handlers are registered, logging exception.
Traceback (most recent call last):
  File "/home/yousefmsm1/Desktop/1.7/venv/lib/python3.12/site-packages/telegram/ext/updater.py", line 651, in _network_loop_retry
    if not action_cb():
           ^^^^^^^^^^^
  File "/home/yousefmsm1/Desktop/1.7/venv/lib/python3.12/site-packages/telegram/ext/updater.py", line 602, in polling_action_cb
    updates = self.bot.get_updates(
              ^^^^^^^^^^^^^^^^^^^^^
  File "/home/yousefmsm1/Desktop/1.7/venv/lib/python3.12/site-packages/telegram/ext/extbot.py", line 228, in get_updates
    updates = super().get_updates(
              ^^^^^^^^^^^^^^^^^^^^
  File "/home/yousefmsm1/Desktop/1.7/venv/lib/python3.12/site-packages/telegram/bot.py", line 134, in decorator
    result = func(*args, **kwargs)
             ^^^^^^^^^^^^^^^^^^^^^
  File "/home/yousefmsm1/Desktop/1.7/venv/lib/python3.12/site-packages/telegram/bot.py", line 3140, in get_updates
    self._post(
  File "/home/yousefmsm1/Desktop/1.7/venv/lib/python3.12/site-packages/telegram/bot.py", line 299, in _post
    return self.request.post(
           ^^^^^^^^^^^^^^^^^^
  File "/home/yousefmsm1/Desktop/1.7/venv/lib/python3.12/site-packages/telegram/utils/request.py", line 361, in post
    result = self._request_wrapper(
             ^^^^^^^^^^^^^^^^^^^^^^
  File "/home/yousefmsm1/Desktop/1.7/venv/lib/python3.12/site-packages/telegram/utils/request.py", line 277, in _request_wrapper
    raise Unauthorized(message)
telegram.error.Unauthorized: Unauthorized
2025-06-23 19:49:00,970 - telegram.ext.updater - ERROR - Error while getting Updates: Unauthorized
2025-06-23 19:49:00,971 - telegram.ext.dispatcher - ERROR - No error handlers are registered, logging exception.
Traceback (most recent call last):
  File "/home/yousefmsm1/Desktop/1.7/venv/lib/python3.12/site-packages/telegram/ext/updater.py", line 651, in _network_loop_retry
    if not action_cb():
           ^^^^^^^^^^^
  File "/home/yousefmsm1/Desktop/1.7/venv/lib/python3.12/site-packages/telegram/ext/updater.py", line 602, in polling_action_cb
    updates = self.bot.get_updates(
              ^^^^^^^^^^^^^^^^^^^^^
  File "/home/yousefmsm1/Desktop/1.7/venv/lib/python3.12/site-packages/telegram/ext/extbot.py", line 228, in get_updates
    updates = super().get_updates(
              ^^^^^^^^^^^^^^^^^^^^
  File "/home/yousefmsm1/Desktop/1.7/venv/lib/python3.12/site-packages/telegram/bot.py", line 134, in decorator
    result = func(*args, **kwargs)
             ^^^^^^^^^^^^^^^^^^^^^
  File "/home/yousefmsm1/Desktop/1.7/venv/lib/python3.12/site-packages/telegram/bot.py", line 3140, in get_updates
    self._post(
  File "/home/yousefmsm1/Desktop/1.7/venv/lib/python3.12/site-packages/telegram/bot.py", line 299, in _post
    return self.request.post(
           ^^^^^^^^^^^^^^^^^^
  File "/home/yousefmsm1/Desktop/1.7/venv/lib/python3.12/site-packages/telegram/utils/request.py", line 361, in post
    result = self._request_wrapper(
             ^^^^^^^^^^^^^^^^^^^^^^
  File "/home/yousefmsm1/Desktop/1.7/venv/lib/python3.12/site-packages/telegram/utils/request.py", line 277, in _request_wrapper
    raise Unauthorized(message)
telegram.error.Unauthorized: Unauthorized
2025-06-23 19:49:31,042 - telegram.ext.updater - ERROR - Error while getting Updates: Unauthorized
2025-06-23 19:49:31,042 - telegram.ext.dispatcher - ERROR - No error handlers are registered, logging exception.
Traceback (most recent call last):
  File "/home/yousefmsm1/Desktop/1.7/venv/lib/python3.12/site-packages/telegram/ext/updater.py", line 651, in _network_loop_retry
    if not action_cb():
           ^^^^^^^^^^^
  File "/home/yousefmsm1/Desktop/1.7/venv/lib/python3.12/site-packages/telegram/ext/updater.py", line 602, in polling_action_cb
    updates = self.bot.get_updates(
              ^^^^^^^^^^^^^^^^^^^^^
  File "/home/yousefmsm1/Desktop/1.7/venv/lib/python3.12/site-packages/telegram/ext/extbot.py", line 228, in get_updates
    updates = super().get_updates(
              ^^^^^^^^^^^^^^^^^^^^
  File "/home/yousefmsm1/Desktop/1.7/venv/lib/python3.12/site-packages/telegram/bot.py", line 134, in decorator
    result = func(*args, **kwargs)
             ^^^^^^^^^^^^^^^^^^^^^
  File "/home/yousefmsm1/Desktop/1.7/venv/lib/python3.12/site-packages/telegram/bot.py", line 3140, in get_updates
    self._post(
  File "/home/yousefmsm1/Desktop/1.7/venv/lib/python3.12/site-packages/telegram/bot.py", line 299, in _post
    return self.request.post(
           ^^^^^^^^^^^^^^^^^^
  File "/home/yousefmsm1/Desktop/1.7/venv/lib/python3.12/site-packages/telegram/utils/request.py", line 361, in post
    result = self._request_wrapper(
             ^^^^^^^^^^^^^^^^^^^^^^
  File "/home/yousefmsm1/Desktop/1.7/venv/lib/python3.12/site-packages/telegram/utils/request.py", line 277, in _request_wrapper
    raise Unauthorized(message)
telegram.error.Unauthorized: Unauthorized
2025-06-23 19:50:01,110 - telegram.ext.updater - ERROR - Error while getting Updates: Unauthorized
2025-06-23 19:50:01,111 - telegram.ext.dispatcher - ERROR - No error handlers are registered, logging exception.
Traceback (most recent call last):
  File "/home/yousefmsm1/Desktop/1.7/venv/lib/python3.12/site-packages/telegram/ext/updater.py", line 651, in _network_loop_retry
    if not action_cb():
           ^^^^^^^^^^^
  File "/home/yousefmsm1/Desktop/1.7/venv/lib/python3.12/site-packages/telegram/ext/updater.py", line 602, in polling_action_cb
    updates = self.bot.get_updates(
              ^^^^^^^^^^^^^^^^^^^^^
  File "/home/yousefmsm1/Desktop/1.7/venv/lib/python3.12/site-packages/telegram/ext/extbot.py", line 228, in get_updates
    updates = super().get_updates(
              ^^^^^^^^^^^^^^^^^^^^
  File "/home/yousefmsm1/Desktop/1.7/venv/lib/python3.12/site-packages/telegram/bot.py", line 134, in decorator
    result = func(*args, **kwargs)
             ^^^^^^^^^^^^^^^^^^^^^
  File "/home/yousefmsm1/Desktop/1.7/venv/lib/python3.12/site-packages/telegram/bot.py", line 3140, in get_updates
    self._post(
  File "/home/yousefmsm1/Desktop/1.7/venv/lib/python3.12/site-packages/telegram/bot.py", line 299, in _post
    return self.request.post(
           ^^^^^^^^^^^^^^^^^^
  File "/home/yousefmsm1/Desktop/1.7/venv/lib/python3.12/site-packages/telegram/utils/request.py", line 361, in post
    result = self._request_wrapper(
             ^^^^^^^^^^^^^^^^^^^^^^
  File "/home/yousefmsm1/Desktop/1.7/venv/lib/python3.12/site-packages/telegram/utils/request.py", line 277, in _request_wrapper
    raise Unauthorized(message)
telegram.error.Unauthorized: Unauthorized
2025-06-23 19:50:31,095 - telegram.ext.updater - INFO - Received signal 15 (SIGTERM), stopping...
2025-06-23 19:50:31,095 - apscheduler.scheduler - INFO - Scheduler has been shut down
